{"name": "test_mp_login[13812345678-246811-1381234567]", "status": "broken", "statusDetails": {"message": "FileNotFoundError: [Errno 2] No such file or directory: './image/err.png'", "trace": "self = <scripts.test01_mp_login.TestMpLogin object at 0x000002CBEDDDF250>, username = '13812345678', code = '246811', expect = '1381234567'\n\n    @pytest.mark.parametrize(\"username,code, expect\", read_yaml(\"mp_login.yaml\"))\n    def test_mp_login(self, username, code, expect):\n        print(\"test\")\n        self.mp.page_mp_login(username, code)\n        try:\n            #断言\n>           assert expect == self.mp .page_get_nickname()\nE           AssertionError: assert '1381234567' == '13812345678'\nE             - 13812345678\nE             ?           -\nE             + 1381234567\n\nscripts\\test01_mp_login.py:29: AssertionError\n\nDuring handling of the above exception, another exception occurred:\n\nself = <scripts.test01_mp_login.TestMpLogin object at 0x000002CBEDDDF250>, username = '13812345678', code = '246811', expect = '1381234567'\n\n    @pytest.mark.parametrize(\"username,code, expect\", read_yaml(\"mp_login.yaml\"))\n    def test_mp_login(self, username, code, expect):\n        print(\"test\")\n        self.mp.page_mp_login(username, code)\n        try:\n            #断言\n            assert expect == self.mp .page_get_nickname()\n        except Exception as e:\n            #输出错误信息\n            print(\"错误原因：\", e)\n            #截图\n>           self.mp.base_get_image()\n\nscripts\\test01_mp_login.py:34: \n_ _ _ _ _ _ _ _ _ _ _ _ _ _ _ _ _ _ _ _ _ _ _ _ _ _ _ _ _ _ _ _ _ _ _ _ _ _ _ _ _ _ _ _ _ _ _ _ _ _ _ _ _ _ _ _ _ _ _ _ _ _ _ _ _ _ _ _ _ _ _ _ _ _ _ _ _ \nbase\\base.py:39: in base_get_image\n    self.__base_write_img()\n_ _ _ _ _ _ _ _ _ _ _ _ _ _ _ _ _ _ _ _ _ _ _ _ _ _ _ _ _ _ _ _ _ _ _ _ _ _ _ _ _ _ _ _ _ _ _ _ _ _ _ _ _ _ _ _ _ _ _ _ _ _ _ _ _ _ _ _ _ _ _ _ _ _ _ _ _ \n\nself = <page.page_mp_login.PageMpLogin object at 0x000002CBEDDDE040>\n\n    def __base_write_img(self):\n>       with open (\"./image/err.png\",\"rb\") as f:\nE       FileNotFoundError: [Errno 2] No such file or directory: './image/err.png'\n\nbase\\base.py:42: FileNotFoundError"}, "parameters": [{"name": "username", "value": "'13812345678'"}, {"name": "code", "value": "'246811'"}, {"name": "expect", "value": "'1381234567'"}], "start": 1616830717963, "stop": 1616830720360, "uuid": "00d7ee41-7b8c-4e9b-becb-e4ba8ff290e1", "historyId": "8d267ff85aa526c094c2fe13962261e3", "testCaseId": "b1928a7174b0d14afd7479ec3844ea33", "fullName": "scripts.test01_mp_login.TestMpLogin#test_mp_login", "labels": [{"name": "parentSuite", "value": "scripts"}, {"name": "suite", "value": "test01_mp_login"}, {"name": "subSuite", "value": "TestMpLogin"}, {"name": "host", "value": "fanxx"}, {"name": "thread", "value": "10992-MainThread"}, {"name": "framework", "value": "pytest"}, {"name": "language", "value": "cpython3"}, {"name": "package", "value": "scripts.test01_mp_login"}]}